Workbook

Sheet 01_Raw_Data
A1: AI Business Analyst — Raw Sales Data
A2: Portfolio dataset: 150+ transactions with intentional text inconsistencies/duplicates for cleaning practice.
A4: Order ID | B4: Order Date | C4: Product | D4: Category | E4: Customer | F4: Region | G4: Channel | H4: Salesperson | I4: Quantity | J4: Unit Price | K4: Revenue | L4: Notes
A5: 1001 | B5: 46080 | C5: Smartphone | D5: Electronics | E5: ABC Electronics | F5: West | G5: Distributor | H5: Kabir | I5: 2 | J5: 30000 | K5: 60000 | L5: Priority
A6: 1002 | B6: 46030 | C6: Smartphone | D6: Electronics | E6: XYZ Retail | F6: North | G6: Distributor | H6: Meera | I6: 1 | J6: 30000 | K6: 30000
A7: 1003 | B7: 46166 | C7: Monitor | D7: Electronics | E7: Tech World | F7: West | G7: Distributor | H7: Rohan | I7: 1 | J7: 15000 | K7: 15000 | L7: Priority
A8: 1004 | B8: 46024 | C8: Desk | D8: Furniture | E8: Tech World | F8: West | G8: Store | H8: Rohan | I8: 3 | J8: 12000 | K8: 36000 | L8: Priority
A9: 1005 | B9: 46109 | C9: Desk | D9: Furniture | E9: Metro Traders | F9: North | G9: Store | H9: Diya | I9: 2 | J9: 12000 | K9: 24000
A10: 1006 | B10: 46177 | C10: Smartphone | D10: Electronics | E10: Prime Retail | F10: South | G10: Online | H10: Kabir | I10: 3 | J10: 30000 | K10: 90000 | L10: Repeat customer
A11: 1007 | B11: 46043 | C11: Laptop | D11: Electronics | E11: Urban Store | F11: East | G11: Distributor | H11: Aarav | I11: 4 | J11: 50000 | K11: 200000
A12: 1008 | B12: 46034 | C12: Keyboard | D12: Electronics | E12: Metro Traders | F12: North | G12: Distributor | H12: Diya | I12: 1 | J12: 2500 | K12: 2500 | L12: Priority
A13: 1009 | B13: 46094 | C13: Keyboard | D13: Electronics | E13: XYZ Retail | F13: North | G13: Online | H13: Aarav | I13: 4 | J13: 2500 | K13: 10000 | L13: Promo
A14: 1010 | B14: 46194 | C14: Office Chair | D14: Furniture | E14: PQR Stores | F14: South | G14: Store | H14: Kabir | I14: 2 | J14: 8000 | K14: 16000 | L14: Repeat customer
A15: 1011 | B15: 46064 | C15: Smartphone | D15: Electronics | E15: PQR Stores | F15: South | G15: Distributor | H15: Isha | I15: 2 | J15: 30000 | K15: 60000 | L15: Promo
A16: 1012 | B16: 46079 | C16: Desk | D16: Furniture | E16: Smart Mart | F16: East | G16: Distributor | H16: Isha | I16: 5 | J16: 12000 | K16: 60000 | L16: Repeat customer
A17: 1013 | B17: 46091 | C17: Laptop | D17: Electronics | E17: Tech World | F17: West | G17: Online | H17: Kabir | I17: 4 | J17: 50000 | K17: 200000
A18: 1014 | B18: 46124 | C18: Monitor | D18: Electronics | E18: Metro Traders | F18: North | G18: Online | H18: Isha | I18: 4 | J18: 15000 | K18: 60000 | L18: Promo
A19: 1015 | B19: 46160 | C19: Headphones | D19: Electronics | E19: Smart Mart | F19: East | G19: Online | H19: Diya | I19: 5 | J19: 3000 | K19: 15000 | L19: Repeat customer
A20: 1016 | B20: 46153 | C20: Desk | D20: Furniture | E20: Prime Retail | F20: South | G20: Store | H20: Diya | I20: 2 | J20: 12000 | K20: 24000 | L20: Promo
A21: 1017 | B21: 46197 | C21: Smartphone | D21: Electronics | E21: ABC Electronics | F21: West | G21: Online | H21: Diya | I21: 2 | J21: 30000 | K21: 60000 | L21: Promo
A22: 1018 | B22: 46158 | C22: Smartphone | D22: Electronics | E22: Prime Retail | F22: South | G22: Store | H22: Rohan | I22: 4 | J22: 30000 | K22: 120000 | L22: Repeat customer
A23: 1019 | B23: 46187 | C23: Laptop | D23: Electronics | E23: XYZ RETAIL | F23: North | G23: Distributor | H23: Rohan | I23: 3 | J23: 50000 | K23: 150000 | L23: Repeat customer
A24: 1020 | B24: 46023 | C24: Smartphone | D24: Electronics | E24: Smart Mart | F24: East | G24: Store | H24: Diya | I24: 4 | J24: 30000 | K24: 120000 | L24: Repeat customer
A25: 1021 | B25: 46178 | C25: Headphones | D25: Electronics | E25: XYZ Retail | F25: North | G25: Distributor | H25: Kabir | I25: 5 | J25: 3000 | K25: 15000 | L25: Priority
A26: 1022 | B26: 46023 | C26: Headphones | D26: Electronics | E26: Metro Traders | F26: North | G26: Online | H26: Rohan | I26: 5 | J26: 3000 | K26: 15000
A27: 1023 | B27: 46101 | C27: Office Chair | D27: Furniture | E27: urban store | F27: East | G27: Online | H27: Aarav | I27: 3 | J27: 8000 | K27: 24000 | L27: Priority
A28: 1024 | B28: 46147 | C28: Laptop | D28: Electronics | E28: Tech World | F28: West | G28: Distributor | H28: Aarav | I28: 1 | J28: 50000 | K28: 50000
A29: 1025 | B29: 46065 | C29: Headphones | D29: Electronics | E29: PQR Stores | F29: South | G29: Distributor | H29: Meera | I29: 5 | J29: 3000 | K29: 15000 | L29: Repeat customer
A30: 1026 | B30: 46102 | C30: Desk | D30: Furniture | E30: Tech World | F30: West | G30: Distributor | H30: Isha | I30: 2 | J30: 12000 | K30: 24000 | L30: Promo
A31: 1027 | B31: 46086 | C31: Office Chair | D31: Furniture | E31: Urban Store | F31: East | G31: Distributor | H31: Meera | I31: 1 | J31: 8000 | K31: 8000 | L31: Priority
A32: 1028 | B32: 46081 | C32: Smartphone | D32: Electronics | E32: Metro Traders | F32: North | G32: Online | H32: Rohan | I32: 5 | J32: 30000 | K32: 150000
A33: 1029 | B33: 46081 | C33: Monitor | D33: Electronics | E33: ABC Electronics | F33: west | G33: Online | H33: Isha | I33: 1 | J33: 15000 | K33: 15000
A34: 1030 | B34: 46094 | C34: Laptop | D34: Electronics | E34: Metro Traders | F34: North | G34: Online | H34: Rohan | I34: 2 | J34: 50000 | K34: 100000 | L34: Promo
A35: 1031 | B35: 46144 | C35: Monitor | D35: Electronics | E35: PQR Stores | F35: South | G35: Distributor | H35: Rohan | I35: 5 | J35: 15000 | K35: 75000 | L35: Priority
A36: 1032 | B36: 46191 | C36: Bookshelf | D36: Furniture | E36: Prime Retail | F36: South | G36: Online | H36: Aarav | I36: 1 | J36: 7000 | K36: 7000 | L36: Promo
A37: 1033 | B37: 46195 | C37: Office Chair | D37: Furniture | E37: Prime Retail | F37: South | G37: Store | H37: Meera | I37: 1 | J37: 8000 | K37: 8000
A38: 1034 | B38: 46086 | C38: Laptop | D38: Electronics | E38: Prime Retail | F38: South | G38: Distributor | H38: Kabir | I38: 1 | J38: 50000 | K38: 50000 | L38: Priority
A39: 1035 | B39: 46094 | C39: Monitor | D39: Electronics | E39: Urban Store | F39: East | G39: Online | H39: Meera | I39: 2 | J39: 15000 | K39: 30000 | L39: Promo
A40: 1036 | B40: 46035 | C40: Monitor | D40: Electronics | E40: XYZ Retail | F40: North | G40: Store | H40: Rohan | I40: 1 | J40: 15000 | K40: 15000
A41: 1037 | B41: 46147 | C41: Laptop | D41: Electronics | E41: XYZ Retail | F41: North | G41: Online | H41: Diya | I41: 4 | J41: 50000 | K41: 200000 | L41: Promo
...

Sheet 00_Instructions
A1: AI Business Analyst — Excel Portfolio Workbook
A2: A practical Excel project designed to demonstrate analyst skills, not just a pretty dashboard.
A4: Step | B4: Sheet | C4: What to do
A5: 1 | B5: Start with 01_Raw_Data | C5: Review the raw transactions, filters, table structure and intentional data-quality issues.
A6: 2 | B6: Open 02_Clean_Data | C6: See formula-driven cleaning and calculated columns.
A7: 3 | B7: Study 03_Lookups | C7: Understand XLOOKUP and INDEX-MATCH reference logic.
A8: 4 | B8: Practice 04_Formula_Analysis | C8: Use the formulas as interview examples.
A9: 5 | B9: Review 05_Pivot_Style | C9: Explain how grouped summaries answer business questions.
A10: 6 | B10: Use 07_Interactive_Analysis | C10: Change dropdowns and observe SUMIFS / COUNTIFS results.
A11: 7 | B11: Present 08_Executive_Dashboard | C11: Use this page as the management-facing output.
A12: 8 | B12: Use 10_Excel_Skills | C12: Use it as your interview revision checklist.

Sheet 02_Clean_Data
A1: Data Cleaning & Calculated Columns
A2: Formula-driven cleaning: TRIM, PROPER, IFERROR, date extraction, revenue checks, profit and margin calculations.
A4: Order ID | B4: Order Date | C4: Product | D4: Category | E4: Customer | F4: Region | G4: Channel | H4: Salesperson | I4: Quantity | J4: Unit Price | K4: Revenue | L4: Year | M4: Month | N4: Clean Customer | O4: Clean Product | P4: Profit | Q4: Profit Margin | R4: Revenue Band
A5: ='01_Raw_Data'!A5 | B5: ='01_Raw_Data'!B5 | C5: =PROPER(TRIM('01_Raw_Data'!C5)) | D5: =PROPER(TRIM('01_Raw_Data'!D5)) | E5: =PROPER(TRIM('01_Raw_Data'!E5)) | F5: =PROPER(TRIM('01_Raw_Data'!F5)) | G5: =PROPER(TRIM('01_Raw_Data'!G5)) | H5: =PROPER(TRIM('01_Raw_Data'!H5)) | I5: ='01_Raw_Data'!I5 | J5: ='01_Raw_Data'!J5 | K5: =IFERROR(I5*J5,0) | L5: =YEAR(B5) | M5: =TEXT(B5,"mmm") | N5: =PROPER(TRIM(E5)) | O5: =PROPER(TRIM(C5)) | P5: =K5*IFERROR(XLOOKUP(D5,'03_Lookups'!$E$5:$E$6,'03_Lookups'!$F$5:$F$6),0) | Q5: =IFERROR(P5/K5,0) | R5: =IFS(K5>=50000,"High",K5>=20000,"Medium",TRUE,"Low")
A6: ='01_Raw_Data'!A6 | B6: ='01_Raw_Data'!B6 | C6: =PROPER(TRIM('01_Raw_Data'!C6)) | D6: =PROPER(TRIM('01_Raw_Data'!D6)) | E6: =PROPER(TRIM('01_Raw_Data'!E6)) | F6: =PROPER(TRIM('01_Raw_Data'!F6)) | G6: =PROPER(TRIM('01_Raw_Data'!G6)) | H6: =PROPER(TRIM('01_Raw_Data'!H6)) | I6: ='01_Raw_Data'!I6 | J6: ='01_Raw_Data'!J6 | K6: =IFERROR(I6*J6,0) | L6: =YEAR(B6) | M6: =TEXT(B6,"mmm") | N6: =PROPER(TRIM(E6)) | O6: =PROPER(TRIM(C6)) | P6: =K6*IFERROR(XLOOKUP(D6,'03_Lookups'!$E$5:$E$6,'03_Lookups'!$F$5:$F$6),0) | Q6: =IFERROR(P6/K6,0) | R6: =IFS(K6>=50000,"High",K6>=20000,"Medium",TRUE,"Low")
A7: ='01_Raw_Data'!A7 | B7: ='01_Raw_Data'!B7 | C7: =PROPER(TRIM('01_Raw_Data'!C7)) | D7: =PROPER(TRIM('01_Raw_Data'!D7)) | E7: =PROPER(TRIM('01_Raw_Data'!E7)) | F7: =PROPER(TRIM('01_Raw_Data'!F7)) | G7: =PROPER(TRIM('01_Raw_Data'!G7)) | H7: =PROPER(TRIM('01_Raw_Data'!H7)) | I7: ='01_Raw_Data'!I7 | J7: ='01_Raw_Data'!J7 | K7: =IFERROR(I7*J7,0) | L7: =YEAR(B7) | M7: =TEXT(B7,"mmm") | N7: =PROPER(TRIM(E7)) | O7: =PROPER(TRIM(C7)) | P7: =K7*IFERROR(XLOOKUP(D7,'03_Lookups'!$E$5:$E$6,'03_Lookups'!$F$5:$F$6),0) | Q7: =IFERROR(P7/K7,0) | R7: =IFS(K7>=50000,"High",K7>=20000,"Medium",TRUE,"Low")
A8: ='01_Raw_Data'!A8 | B8: ='01_Raw_Data'!B8 | C8: =PROPER(TRIM('01_Raw_Data'!C8)) | D8: =PROPER(TRIM('01_Raw_Data'!D8)) | E8: =PROPER(TRIM('01_Raw_Data'!E8)) | F8: =PROPER(TRIM('01_Raw_Data'!F8)) | G8: =PROPER(TRIM('01_Raw_Data'!G8)) | H8: =PROPER(TRIM('01_Raw_Data'!H8)) | I8: ='01_Raw_Data'!I8 | J8: ='01_Raw_Data'!J8 | K8: =IFERROR(I8*J8,0) | L8: =YEAR(B8) | M8: =TEXT(B8,"mmm") | N8: =PROPER(TRIM(E8)) | O8: =PROPER(TRIM(C8)) | P8: =K8*IFERROR(XLOOKUP(D8,'03_Lookups'!$E$5:$E$6,'03_Lookups'!$F$5:$F$6),0) | Q8: =IFERROR(P8/K8,0) | R8: =IFS(K8>=50000,"High",K8>=20000,"Medium",TRUE,"Low")
A9: ='01_Raw_Data'!A9 | B9: ='01_Raw_Data'!B9 | C9: =PROPER(TRIM('01_Raw_Data'!C9)) | D9: =PROPER(TRIM('01_Raw_Data'!D9)) | E9: =PROPER(TRIM('01_Raw_Data'!E9)) | F9: =PROPER(TRIM('01_Raw_Data'!F9)) | G9: =PROPER(TRIM('01_Raw_Data'!G9)) | H9: =PROPER(TRIM('01_Raw_Data'!H9)) | I9: ='01_Raw_Data'!I9 | J9: ='01_Raw_Data'!J9 | K9: =IFERROR(I9*J9,0) | L9: =YEAR(B9) | M9: =TEXT(B9,"mmm") | N9: =PROPER(TRIM(E9)) | O9: =PROPER(TRIM(C9)) | P9: =K9*IFERROR(XLOOKUP(D9,'03_Lookups'!$E$5:$E$6,'03_Lookups'!$F$5:$F$6),0) | Q9: =IFERROR(P9/K9,0) | R9: =IFS(K9>=50000,"High",K9>=20000,"Medium",TRUE,"Low")
A10: ='01_Raw_Data'!A10 | B10: ='01_Raw_Data'!B10 | C10: =PROPER(TRIM('01_Raw_Data'!C10)) | D10: =PROPER(TRIM('01_Raw_Data'!D10)) | E10: =PROPER(TRIM('01_Raw_Data'!E10)) | F10: =PROPER(TRIM('01_Raw_Data'!F10)) | G10: =PROPER(TRIM('01_Raw_Data'!G10)) | H10: =PROPER(TRIM('01_Raw_Data'!H10)) | I10: ='01_Raw_Data'!I10 | J10: ='01_Raw_Data'!J10 | K10: =IFERROR(I10*J10,0) | L10: =YEAR(B10) | M10: =TEXT(B10,"mmm") | N10: =PROPER(TRIM(E10)) | O10: =PROPER(TRIM(C10)) | P10: =K10*IFERROR(XLOOKUP(D10,'03_Lookups'!$E$5:$E$6,'03_Lookups'!$F$5:$F$6),0) | Q10: =IFERROR(P10/K10,0) | R10: =IFS(K10>=50000,"High",K10>=20000,"Medium",TRUE,"Low")
A11: ='01_Raw_Data'!A11 | B11: ='01_Raw_Data'!B11 | C11: =PROPER(TRIM('01_Raw_Data'!C11)) | D11: =PROPER(TRIM('01_Raw_Data'!D11)) | E11: =PROPER(TRIM('01_Raw_Data'!E11)) | F11: =PROPER(TRIM('01_Raw_Data'!F11)) | G11: =PROPER(TRIM('01_Raw_Data'!G11)) | H11: =PROPER(TRIM('01_Raw_Data'!H11)) | I11: ='01_Raw_Data'!I11 | J11: ='01_Raw_Data'!J11 | K11: =IFERROR(I11*J11,0) | L11: =YEAR(B11) | M11: =TEXT(B11,"mmm") | N11: =PROPER(TRIM(E11)) | O11: =PROPER(TRIM(C11)) | P11: =K11*IFERROR(XLOOKUP(D11,'03_Lookups'!$E$5:$E$6,'03_Lookups'!$F$5:$F$6),0) | Q11: =IFERROR(P11/K11,0) | R11: =IFS(K11>=50000,"High",K11>=20000,"Medium",TRUE,"Low")
A12: ='01_Raw_Data'!A12 | B12: ='01_Raw_Data'!B12 | C12: =PROPER(TRIM('01_Raw_Data'!C12)) | D12: =PROPER(TRIM('01_Raw_Data'!D12)) | E12: =PROPER(TRIM('01_Raw_Data'!E12)) | F12: =PROPER(TRIM('01_Raw_Data'!F12)) | G12: =PROPER(TRIM('01_Raw_Data'!G12)) | H12: =PROPER(TRIM('01_Raw_Data'!H12)) | I12: ='01_Raw_Data'!I12 | J12: ='01_Raw_Data'!J12 | K12: =IFERROR(I12*J12,0) | L12: =YEAR(B12) | M12: =TEXT(B12,"mmm") | N12: =PROPER(TRIM(E12)) | O12: =PROPER(TRIM(C12)) | P12: =K12*IFERROR(XLOOKUP(D12,'03_Lookups'!$E$5:$E$6,'03_Lookups'!$F$5:$F$6),0) | Q12: =IFERROR(P12/K12,0) | R12: =IFS(K12>=50000,"High",K12>=20000,"Medium",TRUE,"Low")
A13: ='01_Raw_Data'!A13 | B13: ='01_Raw_Data'!B13 | C13: =PROPER(TRIM('01_Raw_Data'!C13)) | D13: =PROPER(TRIM('01_Raw_Data'!D13)) | E13: =PROPER(TRIM('01_Raw_Data'!E13)) | F13: =PROPER(TRIM('01_Raw_Data'!F13)) | G13: =PROPER(TRIM('01_Raw_Data'!G13)) | H13: =PROPER(TRIM('01_Raw_Data'!H13)) | I13: ='01_Raw_Data'!I13 | J13: ='01_Raw_Data'!J13 | K13: =IFERROR(I13*J13,0) | L13: =YEAR(B13) | M13: =TEXT(B13,"mmm") | N13: =PROPER(TRIM(E13)) | O13: =PROPER(TRIM(C13)) | P13: =K13*IFERROR(XLOOKUP(D13,'03_Lookups'!$E$5:$E$6,'03_Lookups'!$F$5:$F$6),0) | Q13: =IFERROR(P13/K13,0) | R13: =IFS(K13>=50000,"High",K13>=20000,"Medium",TRUE,"Low")
A14: ='01_Raw_Data'!A14 | B14: ='01_Raw_Data'!B14 | C14: =PROPER(TRIM('01_Raw_Data'!C14)) | D14: =PROPER(TRIM('01_Raw_Data'!D14)) | E14: =PROPER(TRIM('01_Raw_Data'!E14)) | F14: =PROPER(TRIM('01_Raw_Data'!F14)) | G14: =PROPER(TRIM('01_Raw_Data'!G14)) | H14: =PROPER(TRIM('01_Raw_Data'!H14)) | I14: ='01_Raw_Data'!I14 | J14: ='01_Raw_Data'!J14 | K14: =IFERROR(I14*J14,0) | L14: =YEAR(B14) | M14: =TEXT(B14,"mmm") | N14: =PROPER(TRIM(E14)) | O14: =PROPER(TRIM(C14)) | P14: =K14*IFERROR(XLOOKUP(D14,'03_Lookups'!$E$5:$E$6,'03_Lookups'!$F$5:$F$6),0) | Q14: =IFERROR(P14/K14,0) | R14: =IFS(K14>=50000,"High",K14>=20000,"Medium",TRUE,"Low")
A15: ='01_Raw_Data'!A15 | B15: ='01_Raw_Data'!B15 | C15: =PROPER(TRIM('01_Raw_Data'!C15)) | D15: =PROPER(TRIM('01_Raw_Data'!D15)) | E15: =PROPER(TRIM('01_Raw_Data'!E15)) | F15: =PROPER(TRIM('01_Raw_Data'!F15)) | G15: =PROPER(TRIM('01_Raw_Data'!G15)) | H15: =PROPER(TRIM('01_Raw_Data'!H15)) | I15: ='01_Raw_Data'!I15 | J15: ='01_Raw_Data'!J15 | K15: =IFERROR(I15*J15,0) | L15: =YEAR(B15) | M15: =TEXT(B15,"mmm") | N15: =PROPER(TRIM(E15)) | O15: =PROPER(TRIM(C15)) | P15: =K15*IFERROR(XLOOKUP(D15,'03_Lookups'!$E$5:$E$6,'03_Lookups'!$F$5:$F$6),0) | Q15: =IFERROR(P15/K15,0) | R15: =IFS(K15>=50000,"High",K15>=20000,"Medium",TRUE,"Low")
A16: ='01_Raw_Data'!A16 | B16: ='01_Raw_Data'!B16 | C16: =PROPER(TRIM('01_Raw_Data'!C16)) | D16: =PROPER(TRIM('01_Raw_Data'!D16)) | E16: =PROPER(TRIM('01_Raw_Data'!E16)) | F16: =PROPER(TRIM('01_Raw_Data'!F16)) | G16: =PROPER(TRIM('01_Raw_Data'!G16)) | H16: =PROPER(TRIM('01_Raw_Data'!H16)) | I16: ='01_Raw_Data'!I16 | J16: ='01_Raw_Data'!J16 | K16: =IFERROR(I16*J16,0) | L16: =YEAR(B16) | M16: =TEXT(B16,"mmm") | N16: =PROPER(TRIM(E16)) | O16: =PROPER(TRIM(C16)) | P16: =K16*IFERROR(XLOOKUP(D16,'03_Lookups'!$E$5:$E$6,'03_Lookups'!$F$5:$F$6),0) | Q16: =IFERROR(P16/K16,0) | R16: =IFS(K16>=50000,"High",K16>=20000,"Medium",TRUE,"Low")
... A157: ='01_Raw_Data'!A157 | B157: ='01_Raw_Data'!B157 | C157: =PROPER(TRIM('01_Raw_Data'!C157)) | D157: =PROPER(TRIM('01_Raw_Data'!D157)) | E157: =PROPER(TRIM('01_Raw_Data'!E157)) | F157: =PROPER(TRIM('01_Raw_Data'!F157)) | G157: =PROPER(TRIM('01_Raw_Data'!G157)) | H157: =PROPER(TRIM('01_Raw_Data'!H157)) | I157: ='01_Raw_Data'!I157 | J157: ='01_Raw_Data'!J157 | K157: =IFERROR(I157*J157,0) | L157: =YEAR(B157) | M157: =TEXT(B157,"mmm") | N157: =PROPER(TRIM(E157)) | O157: =PROPER(TRIM(C157)) | P157: =K157*IFERROR(XLOOKUP(D157,'03_Lookups'!$E$5:$E$6,'03_Lookups'!$F$5:$F$6),0) | Q157: =IFERROR(P157/K157,0) | R157: =IFS(K157>=50000,"High",K157>=20000,"Medium",TRUE,"Low")

Sheet 03_Lookups
A1: Lookup Tables & Reference Data
A2: Demonstrates XLOOKUP / INDEX-MATCH style reference tables and controlled input lists.
A4: Category | B4: Margin Assumption | D4: Product | E4: Category | F4: Margin Assumption | H4: Region List
A5: Electronics | B5: 0.18 | D5: Laptop | E5: Electronics | F5: 0.18 | H5: North
A6: Furniture | B6: 0.2 | D6: Smartphone | E6: Electronics | F6: 0.15 | H6: South
D7: Headphones | E7: Electronics | F7: 0.25 | H7: East
D8: Monitor | E8: Electronics | F8: 0.2 | H8: West
A9: Example XLOOKUP | B9: =XLOOKUP("Laptop",D5:D12,F5:F12) | D9: Keyboard | E9: Electronics | F9: 0.28
A10: Example INDEX-MATCH | B10: =INDEX(E5:E12,MATCH("Desk",D5:D12,0)) | D10: Office Chair | E10: Furniture | F10: 0.22
A11: Example IFERROR | B11: =IFERROR(XLOOKUP("Unknown",D5:D12,F5:F12),"Not Found") | D11: Desk | E11: Furniture | F11: 0.2
D12: Bookshelf | E12: Furniture | F12: 0.19

Sheet 04_Formula_Analysis
A1: Formula-Based Business Analysis
A2: Interview-ready examples using SUM, AVERAGE, COUNTIF(S), SUMIF(S), AVERAGEIF(S), ranking and dynamic selectors.
A4: Metric | B4: Formula / Result
A5: Total Revenue | B5: =SUM('02_Clean_Data'!K5:K157)
A6: Average Order Value | B6: =AVERAGE('02_Clean_Data'!K5:K157)
A7: Total Orders | B7: =COUNTA('02_Clean_Data'!A5:A157)
A8: Electronics Revenue | B8: =SUMIF('02_Clean_Data'!D5:D157,"Electronics",'02_Clean_Data'!K5:K157)
A9: Furniture Revenue | B9: =SUMIF('02_Clean_Data'!D5:D157,"Furniture",'02_Clean_Data'!K5:K157)
A10: West Revenue | B10: =SUMIF('02_Clean_Data'!F5:F157,"West",'02_Clean_Data'!K5:K157)
A11: Online Orders | B11: =COUNTIF('02_Clean_Data'!G5:G157,"Online")
A12: Electronics + Online Revenue | B12: =SUMIFS('02_Clean_Data'!K5:K157,'02_Clean_Data'!D5:D157,"Electronics",'02_Clean_Data'!G5:G157,"Online")
A13: High Revenue Transactions | B13: =COUNTIF('02_Clean_Data'!R5:R157,"High")
A14: Average Electronics Revenue | B14: =AVERAGEIF('02_Clean_Data'!D5:D157,"Electronics",'02_Clean_Data'!K5:K157)
A17: Key Excel Skills
A18: SUM / AVERAGE | B18: Used in this workbook
A19: SUMIF / COUNTIF | B19: Used in this workbook
A20: SUMIFS / COUNTIFS | B20: Used in this workbook
A21: AVERAGEIF(S) | B21: Used in this workbook
A22: IF / IFS / IFERROR | B22: Used in this workbook
A23: Text cleaning | B23: Used in this workbook
A24: Date functions | B24: Used in this workbook
A25: Lookup functions | B25: Used in this workbook

Sheet 05_Pivot_Style
A1: Pivot-Style Analysis
A2: Formula-built summaries that mimic common PivotTable outputs. Use these to explain trends in interviews.
A4: Product | B4: Revenue | C4: Orders | D4: Avg Revenue | E4: Rank | G4: Category | H4: Revenue | I4: Orders | J4: Avg Order Value
A5: Laptop | B5: =SUMIF('02_Clean_Data'!O5:O157,A5,'02_Clean_Data'!K5:K157) | C5: =COUNTIF('02_Clean_Data'!O5:O157,A5) | D5: =IFERROR(B5/C5,0) | E5: =RANK(B5,$B$5:$B$12,0) | G5: Electronics | H5: =SUMIF('02_Clean_Data'!D5:D157,G5,'02_Clean_Data'!K5:K157) | I5: =COUNTIF('02_Clean_Data'!D5:D157,G5) | J5: =IFERROR(H5/I5,0)
A6: Smartphone | B6: =SUMIF('02_Clean_Data'!O5:O157,A6,'02_Clean_Data'!K5:K157) | C6: =COUNTIF('02_Clean_Data'!O5:O157,A6) | D6: =IFERROR(B6/C6,0) | E6: =RANK(B6,$B$5:$B$12,0) | G6: Furniture | H6: =SUMIF('02_Clean_Data'!D5:D157,G6,'02_Clean_Data'!K5:K157) | I6: =COUNTIF('02_Clean_Data'!D5:D157,G6) | J6: =IFERROR(H6/I6,0)
A7: Headphones | B7: =SUMIF('02_Clean_Data'!O5:O157,A7,'02_Clean_Data'!K5:K157) | C7: =COUNTIF('02_Clean_Data'!O5:O157,A7) | D7: =IFERROR(B7/C7,0) | E7: =RANK(B7,$B$5:$B$12,0)
A8: Monitor | B8: =SUMIF('02_Clean_Data'!O5:O157,A8,'02_Clean_Data'!K5:K157) | C8: =COUNTIF('02_Clean_Data'!O5:O157,A8) | D8: =IFERROR(B8/C8,0) | E8: =RANK(B8,$B$5:$B$12,0)
A9: Keyboard | B9: =SUMIF('02_Clean_Data'!O5:O157,A9,'02_Clean_Data'!K5:K157) | C9: =COUNTIF('02_Clean_Data'!O5:O157,A9) | D9: =IFERROR(B9/C9,0) | E9: =RANK(B9,$B$5:$B$12,0)
A10: Office Chair | B10: =SUMIF('02_Clean_Data'!O5:O157,A10,'02_Clean_Data'!K5:K157) | C10: =COUNTIF('02_Clean_Data'!O5:O157,A10) | D10: =IFERROR(B10/C10,0) | E10: =RANK(B10,$B$5:$B$12,0)
A11: Desk | B11: =SUMIF('02_Clean_Data'!O5:O157,A11,'02_Clean_Data'!K5:K157) | C11: =COUNTIF('02_Clean_Data'!O5:O157,A11) | D11: =IFERROR(B11/C11,0) | E11: =RANK(B11,$B$5:$B$12,0)
A12: Bookshelf | B12: =SUMIF('02_Clean_Data'!O5:O157,A12,'02_Clean_Data'!K5:K157) | C12: =COUNTIF('02_Clean_Data'!O5:O157,A12) | D12: =IFERROR(B12/C12,0) | E12: =RANK(B12,$B$5:$B$12,0)

Sheet 06_Monthly_Analysis
A1: Monthly Trend Analysis
A2: Monthly revenue, order count and average order value using SUMIFS / COUNTIFS.
A4: Month | B4: Revenue | C4: Orders | D4: AOV | E4: Revenue Growth | F4: Status
A5: 46023 | B5: =SUMIFS('02_Clean_Data'!K5:K157,'02_Clean_Data'!B5:B157,">="&A5,'02_Clean_Data'!B5:B157,"<"&EDATE(A5,1)) | C5: =COUNTIFS('02_Clean_Data'!B5:B157,">="&A5,'02_Clean_Data'!B5:B157,"<"&EDATE(A5,1)) | D5: =IFERROR(B5/C5,0)
A6: 46054 | B6: =SUMIFS('02_Clean_Data'!K5:K157,'02_Clean_Data'!B5:B157,">="&A6,'02_Clean_Data'!B5:B157,"<"&EDATE(A6,1)) | C6: =COUNTIFS('02_Clean_Data'!B5:B157,">="&A6,'02_Clean_Data'!B5:B157,"<"&EDATE(A6,1)) | D6: =IFERROR(B6/C6,0) | E6: =IFERROR((B6-B5)/B5,0) | F6: =IF(E6>=0,"Growing","Declining")
A7: 46082 | B7: =SUMIFS('02_Clean_Data'!K5:K157,'02_Clean_Data'!B5:B157,">="&A7,'02_Clean_Data'!B5:B157,"<"&EDATE(A7,1)) | C7: =COUNTIFS('02_Clean_Data'!B5:B157,">="&A7,'02_Clean_Data'!B5:B157,"<"&EDATE(A7,1)) | D7: =IFERROR(B7/C7,0) | E7: =IFERROR((B7-B6)/B6,0) | F7: =IF(E7>=0,"Growing","Declining")
A8: 46113 | B8: =SUMIFS('02_Clean_Data'!K5:K157,'02_Clean_Data'!B5:B157,">="&A8,'02_Clean_Data'!B5:B157,"<"&EDATE(A8,1)) | C8: =COUNTIFS('02_Clean_Data'!B5:B157,">="&A8,'02_Clean_Data'!B5:B157,"<"&EDATE(A8,1)) | D8: =IFERROR(B8/C8,0) | E8: =IFERROR((B8-B7)/B7,0) | F8: =IF(E8>=0,"Growing","Declining")
A9: 46143 | B9: =SUMIFS('02_Clean_Data'!K5:K157,'02_Clean_Data'!B5:B157,">="&A9,'02_Clean_Data'!B5:B157,"<"&EDATE(A9,1)) | C9: =COUNTIFS('02_Clean_Data'!B5:B157,">="&A9,'02_Clean_Data'!B5:B157,"<"&EDATE(A9,1)) | D9: =IFERROR(B9/C9,0) | E9: =IFERROR((B9-B8)/B8,0) | F9: =IF(E9>=0,"Growing","Declining")
A10: 46174 | B10: =SUMIFS('02_Clean_Data'!K5:K157,'02_Clean_Data'!B5:B157,">="&A10,'02_Clean_Data'!B5:B157,"<"&EDATE(A10,1)) | C10: =COUNTIFS('02_Clean_Data'!B5:B157,">="&A10,'02_Clean_Data'!B5:B157,"<"&EDATE(A10,1)) | D10: =IFERROR(B10/C10,0) | E10: =IFERROR((B10-B9)/B9,0) | F10: =IF(E10>=0,"Growing","Declining")

Sheet 07_Interactive_Analysis
A1: Interactive Business Analysis
A2: Change the dropdown selections. KPI formulas update using SUMIFS / COUNTIFS.
A4: Selected Region | B4: West | D4: KPI | E4: Value
A5: Selected Category | B5: Electronics | D5: Filtered Revenue | E5: =SUMIFS('02_Clean_Data'!K5:K157,'02_Clean_Data'!F5:F157,B4,'02_Clean_Data'!D5:D157,B5,'02_Clean_Data'!G5:G157,B6)
A6: Selected Channel | B6: Online | D6: Filtered Orders | E6: =COUNTIFS('02_Clean_Data'!F5:F157,B4,'02_Clean_Data'!D5:D157,B5,'02_Clean_Data'!G5:G157,B6)
D7: Filtered AOV | E7: =IFERROR(E5/E6,0)
D8: High Revenue Orders | E8: =COUNTIFS('02_Clean_Data'!F5:F157,B4,'02_Clean_Data'!D5:D157,B5,'02_Clean_Data'!G5:G157,B6,'02_Clean_Data'!R5:R157,"High")
A9: Why this matters
A10: This sheet demonstrates Data Validation + SUMIFS + COUNTIFS + IFERROR. In an interview, explain that dropdowns change the criteria while the formulas recalculate the selected business segment.

Sheet 08_Executive_Dashboard
A1: AI BUSINESS ANALYST — EXECUTIVE DASHBOARD
A2: Management view built from the cleaned sales data. KPI cards + charts + business interpretation.
A4: Total Revenue | D4: Total Orders | G4: Average Order Value | J4: Top Product
A5: =SUM('02_Clean_Data'!K5:K157) | D5: =COUNTA('02_Clean_Data'!A5:A157) | G5: =AVERAGE('02_Clean_Data'!K5:K157) | J5: =INDEX('05_Pivot_Style'!A5:A12,MATCH(MAX('05_Pivot_Style'!B5:B12),'05_Pivot_Style'!B5:B12,0))
A9: Product Revenue | D9: Category Revenue | G9: Monthly Revenue
A10: Product | B10: Revenue | D10: Category | E10: Revenue | G10: Month | H10: Revenue
A11: ='05_Pivot_Style'!A5 | B11: ='05_Pivot_Style'!B5 | D11: ='05_Pivot_Style'!G5 | E11: ='05_Pivot_Style'!H5 | G11: ='06_Monthly_Analysis'!A5 | H11: ='06_Monthly_Analysis'!B5
A12: ='05_Pivot_Style'!A6 | B12: ='05_Pivot_Style'!B6 | D12: ='05_Pivot_Style'!G6 | E12: ='05_Pivot_Style'!H6 | G12: ='06_Monthly_Analysis'!A6 | H12: ='06_Monthly_Analysis'!B6
A13: ='05_Pivot_Style'!A7 | B13: ='05_Pivot_Style'!B7 | G13: ='06_Monthly_Analysis'!A7 | H13: ='06_Monthly_Analysis'!B7
A14: ='05_Pivot_Style'!A8 | B14: ='05_Pivot_Style'!B8 | G14: ='06_Monthly_Analysis'!A8 | H14: ='06_Monthly_Analysis'!B8
A15: ='05_Pivot_Style'!A9 | B15: ='05_Pivot_Style'!B9 | G15: ='06_Monthly_Analysis'!A9 | H15: ='06_Monthly_Analysis'!B9
A16: ='05_Pivot_Style'!A10 | B16: ='05_Pivot_Style'!B10 | G16: ='06_Monthly_Analysis'!A10 | H16: ='06_Monthly_Analysis'!B10
A17: ='05_Pivot_Style'!A11 | B17: ='05_Pivot_Style'!B11
A18: ='05_Pivot_Style'!A12 | B18: ='05_Pivot_Style'!B12

Sheet 09_Cleaning_Guide
A1: Data Cleaning Demonstration
A2: Shows what a real analyst would clean before reporting.
A4: Issue | B4: Example in Raw Data | C4: Cleaning Formula / Method | D4: Why it matters
A5: Extra spaces | B5: Laptop | C5: =PROPER(TRIM(cell)) | D5: Prevents mismatches in lookups and summaries
A6: Inconsistent case | B6: abc electronics | C6: =PROPER(TRIM(cell)) | D6: Standardizes labels
A7: Wrong / missing calculation | B7: Revenue | C7: =IFERROR(Quantity*Unit Price,0) | D7: Creates a reliable metric
A8: Duplicate records | B8: Repeated Order ID | C8: COUNTIF / Remove Duplicates | D8: Prevents double counting
A9: Date analysis | B9: 01-Jan-2026 | C9: YEAR / MONTH / EOMONTH | D9: Enables time-based analysis
A10: Missing lookup | B10: Unknown product | C10: IFERROR(XLOOKUP(...),"Not Found") | D10: Avoids formula errors

Sheet 10_Excel_Skills
A1: Excel Skills Demonstrated
A2: Use this page as a checklist when explaining the workbook in interviews.
A4: Skill | B4: Functions / Feature | C4: How it is used
A5: Data Cleaning | B5: TRIM, PROPER, IFERROR, duplicate awareness | C5: Standardized text and protected calculations from errors.
A6: Excel Tables | B6: Structured Tables + filters + freeze panes | C6: Makes raw data easier to manage and formulas scalable.
A7: Lookup Functions | B7: XLOOKUP, INDEX, MATCH | C7: Connects transactional data with reference/master data.
A8: Conditional Logic | B8: IF, IFS | C8: Creates revenue bands and business classifications.
A9: Conditional Aggregation | B9: SUMIF, SUMIFS, COUNTIF, COUNTIFS, AVERAGEIF | C9: Answers segment-specific business questions.
A10: Date Analysis | B10: YEAR, TEXT, EDATE | C10: Supports monthly trend reporting.
A11: Conditional Formatting | B11: Color scales and data bars | C11: Highlights strong/weak values quickly.
A12: Data Validation | B12: Dropdown selectors | C12: Creates interactive analysis without macros.
A13: Charts | B13: Bar, line, pie | C13: Communicates product, trend and category insights.
A14: Dashboarding | B14: KPI cards + charts | C14: Converts analysis into an executive-friendly view.
A15: Business Analysis | B15: Revenue, AOV, orders, margin | C15: Turns raw transactions into business KPIs.

Sheet 11_Data_Dictionary
A1: Data Dictionary
A2: Definitions of the main fields used in the business analysis.
A4: Field | B4: Definition | C4: Data Type
A5: Order ID | B5: Unique transaction identifier | C5: Integer
A6: Order Date | B6: Date of the transaction | C6: Date
A7: Product | B7: Product sold | C7: Text
A8: Category | B8: Product category | C8: Text
A9: Customer | B9: Customer / account name | C9: Text
A10: Region | B10: Sales region | C10: Text
A11: Channel | B11: Sales channel | C11: Text
A12: Salesperson | B12: Representative handling the transaction | C12: Text
A13: Quantity | B13: Units sold | C13: Integer
A14: Unit Price | B14: Price per unit | C14: Currency
A15: Revenue | B15: Quantity × Unit Price | C15: Currency
... A18: Revenue Band | B18: High / Medium / Low classification | C18: Text
